### `question_172.md`

**Вопрос 172.** Какой из следующих вариантов правильно описывает использование `try`, `except` и `finally` блоков в Python?

A.  Блок `try` содержит код, в котором может возникнуть ошибка, блок `except` выполняется, если ошибки не произошло, и блок `finally` выполняется всегда.
B.  Блок `try` содержит код, который должен быть выполнен только в случае ошибки, а блок `except` и блок `finally` - когда ошибки нет.
C. Блок `try` содержит код, в котором может возникнуть ошибка, блок `except` выполняется, если ошибка произошла, а блок `finally` выполняется всегда.
D. Блок `try` предназначен для выполнения кода несколько раз, а блоки `except` и `finally` используются для обработки итоговых результатов.

**Правильный ответ: C**

**Объяснение:**

Структура `try-except-finally` предназначена для обработки исключений (ошибок) в Python и позволяет более надежно контролировать выполнение кода.

*   **Вариант A** не верен: Блок `except` выполняется при возникновении ошибки, а не при ее отсутствии.
*   **Вариант B** не верен: Блок `try` предназначен для кода, который может *вызвать* ошибку, а не только для кода, который нужно выполнить при её отсутствии.
*   **Вариант C** верен: Этот вариант правильно описывает роли каждого блока.
*   **Вариант D** не верен: `try-except-finally` не предназначены для выполнения кода несколько раз.

**Как работают блоки `try-except-finally`:**

1.  **`try` блок:** Содержит код, в котором может возникнуть исключение.
2.  **`except` блок:** Выполняется в случае возникновения исключения в блоке `try`. Может обрабатывать исключения конкретных типов или все исключения.
3.  **`finally` блок:** Выполняется всегда, независимо от того, было ли исключение и было ли оно поймано в блоке `except`. Обычно используется для действий, которые должны быть выполнены в любом случае (например, освобождение ресурсов).

**Пример:**

```python
try:
    result: float = 10 / 0
except ZeroDivisionError:
    print("Ошибка: Деление на ноль!")
finally:
    print("Блок finally выполняется всегда!")

# Вывод:
# Ошибка: Деление на ноль!
# Блок finally выполняется всегда!


try:
    result: int = 10 + 10
except ZeroDivisionError:
    print("Ошибка: Деление на ноль!") # Не выполнится
finally:
    print("Блок finally выполняется всегда!") # Вывод: Блок finally выполняется всегда!
```

**В результате:**
*   `try` выполняет код, который может вызвать исключение.
*  Если в блоке `try` произойдет ошибка, будет выполнен блок `except`, иначе он будет пропущен.
*   Блок `finally` будет выполнен в любом случае, независимо от того было ли исключение или нет.

Таким образом, **вариант C** является правильным ответом.
