### `question_024.md`

**Вопрос 24.** Блоки `try` и `except` в Python используются для обработки исключений, чтобы перехватывать и управлять ошибками во время выполнения программы. В чем основное преимущество использования этих блоков, и как иерархия исключений Python помогает в перехвате и обработке различных типов исключений, таких как `ZeroDivisionError`, `FileNotFoundError` и общего `Exception`?

A.  Блоки `try` и `except` помогают предотвратить сбои программы, перехватывая исключения, и иерархия исключений Python позволяет перехватывать конкретные исключения до общих, чтобы более точно обрабатывать ошибки.
B.  Использование `try` и `except` гарантирует, что сообщения об ошибках никогда не будут отображаться пользователю, так как все исключения будут игнорироваться без какого-либо вывода.
C.  Блок `try` перехватывает только ошибки времени выполнения, такие как синтаксические ошибки, а блок `except` записывает их в отдельный файл для последующего анализа.
D.  Блоки `try` и `except` используются для повышения производительности путем пропуска разделов кода, которые подвержены сбоям, и они не обрабатывают исключения, выходящие за рамки тех, которые указаны в блоке `except`.

**Правильный ответ: A**

**Объяснение:**

Блоки `try` и `except` в Python являются фундаментальным механизмом обработки исключений, который помогает сделать программы более надежными.

*   **`try` блок:** Этот блок содержит код, который потенциально может вызвать исключение. Исключение может возникнуть в результате ошибки во время выполнения программы (например, деление на ноль или попытка открыть несуществующий файл).
*   **`except` блок:** Этот блок содержит код, который выполняется, когда возникает исключение в блоке `try`. Он перехватывает исключение и обрабатывает его, предотвращая аварийное завершение программы. Вы можете указать тип исключения, которое хотите обработать, чтобы конкретизировать, какие ошибки будут отловлены.

**Иерархия исключений Python:**

Python имеет иерархию исключений, где исключения организованы от более общих к более конкретным. Это позволяет перехватывать исключения на разных уровнях:

*   `Exception` является базовым классом для всех исключений.
*   `ZeroDivisionError` и `FileNotFoundError` являются более конкретными исключениями, которые наследуются от `Exception`.

Благодаря этой иерархии, можно перехватывать общие исключения `Exception`, а можно перехватывать более конкретные исключения, например `ZeroDivisionError` или `FileNotFoundError`, которые наследуются от `Exception`.

Теперь рассмотрим варианты ответа:

*   **Вариант A** является правильным, поскольку точно описывает, как `try` и `except` работают, и как иерархия исключений позволяет обрабатывать ошибки более точно.
*   **Вариант B** не верен: `try` и `except` используются для корректной обработки ошибок, а не для их игнорирования.
*   **Вариант C** не верен: Блок `try` может перехватывать и синтаксические ошибки, блок `except` предназначен для вывода сообщений и не занимается логированием.
*   **Вариант D** не верен: `try` и `except` перехватывают ошибки в коде, который может упасть, а не игнорируют его.

**Пример:**

```python
try:
  result: float = 10 / 0 # Возникнет ZeroDivisionError
except ZeroDivisionError:
    print("Ошибка: Деление на ноль!")
except FileNotFoundError: # Это исключение не произойдет
  print("Ошибка: Файл не найден!")
except Exception as e: # Более общее исключение для остальных случаев
   print(f"Произошла ошибка: {e}")

try:
    with open("not_existing_file.txt", "r") as file:
        content = file.read()
except FileNotFoundError: # Возникнет FileNotFoundError
    print("Ошибка: Файл не найден!")
except Exception as e: # Более общее исключение для остальных случаев
   print(f"Произошла ошибка: {e}")
```

**В результате:**
* Первый блок `try` приведет к возникновению `ZeroDivisionError`, которое будет перехвачено в блоке `except ZeroDivisionError` и программа выведет сообщение "Ошибка: Деление на ноль!".
* Второй блок `try` вызовет ошибку `FileNotFoundError`, поскольку файл "not_existing_file.txt" не существует. `except FileNotFoundError` отловит это исключение и программа выведет "Ошибка: Файл не найден!".

Таким образом, **вариант A** является правильным, так как он точно описывает, как работает механизм `try-except` с иерархией исключений.
