### `question_010.md`

**Вопрос 10.** Рассмотрите блок кода Python для обработки исключений при попытке преобразовать целое число из пользовательского ввода, используя функцию `input()`. Какая реализация правильно обрабатывает ввод, который может быть недействительным целым числом, например 'пять', и выводит сообщение об ошибке?

```python
A. try: num = int(input("Введите число: ")) except ValueError: print("Это не является действительным числом!")
B. try: num = int(input("Введите число: ")) if not num: print("Это не является действительным числом!")
C. num = int(input("Введите число: ")) except ValueError: print("Это не является действительным числом!")
D. try: num = int(input("Введите число: ")) catch (ValueError): print("Это не является действительным числом!")
```

**Правильный ответ: A**

**Объяснение:**

Для обработки исключений, возникающих при попытке преобразования неверного ввода пользователя в целое число (например, при вводе слова вместо числа), используется конструкция `try...except`.

*   **`try`** блок: содержит код, который может вызвать исключение. В данном случае это попытка преобразования строки, полученной от пользователя, в целое число с помощью функции `int()`.
*   **`except`** блок: содержит код, который выполняется, если в блоке `try` возникает указанное исключение. В нашем случае это исключение `ValueError`, которое возникает при неудачной попытке преобразования строки в целое число.

Теперь разберем каждый вариант:

*   **Вариант A:** `try: num = int(input("Введите число: ")) except ValueError: print("Это не является действительным числом!")` - это правильная реализация. Она корректно пытается преобразовать ввод в число, и если возникает ошибка `ValueError` (например, если пользователь введет "пять"), программа перехватывает исключение и выводит соответствующее сообщение об ошибке.
    
*   **Вариант B:** `try: num = int(input("Введите число: ")) if not num: print("Это не является действительным числом!")` - содержит синтаксическую ошибку и не сможет обработать исключение. `if not num:`  не будет выполнено, если возникает исключение `ValueError`, поскольку переменной `num` не будет присвоено значения.
    
*   **Вариант C:** `num = int(input("Введите число: ")) except ValueError: print("Это не является действительным числом!")` - отсутствует ключевое слово `try` для начала блока, который может вызывать исключение, поэтому возникает синтаксическая ошибка.
    
*   **Вариант D:** `try: num = int(input("Введите число: ")) catch (ValueError): print("Это не является действительным числом!")` - содержит синтаксическую ошибку: ключевое слово `catch` не используется в Python для обработки исключений, используется `except`.

**Пример:**

```python
# Пример с правильной реализацией (вариант А)
try:
    num: int = int(input("Введите число: "))
    print(f"Вы ввели число: {num}")
except ValueError:
    print("Это не является действительным числом!")

# Пример ввода неверного значения
try:
    num: int = int(input("Введите число: "))
    print(f"Вы ввели число: {num}")
except ValueError:
    print("Это не является действительным числом!")
```

**В результате:**

В первом примере если ввести "123" - выведется "Вы ввели число: 123". Во втором примере если ввести "пять" - будет перехвачено исключение `ValueError`, и выведется сообщение "Это не является действительным числом!".

Таким образом, только **вариант A** корректно обрабатывает исключение `ValueError` и выводит соответствующее сообщение об ошибке.
