### `question_037.md`

**Вопрос 37.** Как обработка исключений в Python с помощью блоков `try-except` помогает в надежной разработке программ, особенно с точки зрения непрерывности работы и управления ошибками?

A.  Блоки `try-except` в Python предназначены только для перехвата синтаксических ошибок в коде, позволяя программам быть синтаксически правильными и безошибочными.
B.  Эти блоки используются для тестирования блока кода на наличие ошибок, перехвата возникающих исключений и обработки их в блоке `except`, что предотвращает внезапное завершение программы.
C.  Структура `try-except` автоматически исправляет логические ошибки в коде, гарантируя выполнение намеченных операций без ручного вмешательства.
D.  Эта конструкция используется для повышения скорости выполнения кода путем игнорирования исключений, которые не являются критическими для основной функциональности приложения.

**Правильный ответ: B**

**Объяснение:**

Блоки `try-except` являются фундаментальным механизмом в Python для обработки исключений, которые могут возникать во время выполнения программы. Эти блоки позволяют создавать надежные программы, устойчивые к ошибкам.

*   **`try` блок:** Содержит код, в котором может возникнуть исключение (ошибка времени выполнения).
*   **`except` блок:** Содержит код, который выполняется, если в блоке `try` возникает исключение. В блоке except можно определить, как именно обрабатывать исключение, чтобы предотвратить аварийное завершение программы.

Теперь рассмотрим варианты ответов:

*   **Вариант A** не верен: `try-except` предназначены для перехвата ошибок *времени выполнения*, а не синтаксических.
*   **Вариант B** верен: Блоки `try-except` действительно позволяют перехватывать исключения и корректно их обрабатывать, что препятствует внезапному завершению программы.
*   **Вариант C** не верен: `try-except` не исправляют логические ошибки автоматически, они перехватывают исключения.
*   **Вариант D** не верен: `try-except` не игнорируют исключения, а обрабатывают их.

**Как `try-except` помогают в надежной разработке:**

1.  **Предотвращение сбоев:**  `try-except` позволяет перехватывать исключения и продолжать выполнение программы, а не завершать ее аварийно.
2.  **Обработка ошибок:** `except` блок позволяет разработчику обрабатывать исключение, например, вывести сообщение об ошибке, выполнить какие-то действия по восстановлению, или корректно завершить работу программы.
3.  **Контроль потока выполнения:** позволяет продолжать выполнение программы, когда происходит ошибка, перенаправляя ход выполнения в блок `except`.
4.  **Улучшение опыта пользователя:**  Блоки `try-except` позволяют показывать пользователям более информативные сообщения об ошибках, а не просто наблюдать аварийное завершение программы.

**Пример:**

```python
def divide(x: int, y: int) -> float:
    try:
      result: float = x / y
      print(f"Результат: {result}")
      return result
    except ZeroDivisionError:
       print("Ошибка: Деление на ноль!")
       return None

divide(10, 2)   # Вывод:  Результат: 5.0
divide(10, 0) # Вывод: Ошибка: Деление на ноль!
```

**В результате:**

*   В примере выше функция `divide()` корректно делит число `x` на `y`.
*   Если `y` будет равен 0, то будет перехвачено исключение `ZeroDivisionError`, и программа выведет сообщение `"Ошибка: Деление на ноль!"` и вернёт `None`, а не завершит работу аварийно.

Таким образом, **вариант B** является верным ответом.
