### `question_504.md`
**Вопрос 504:**
```python
def foo():
    try:
        return 1
    finally:
        return 2
result = foo()
print(result)
```
Какой будет результат выполнения этого кода?

A. 1
B. 2
C. None
D. Произойдет ошибка

**Правильный ответ: B**

**Объяснение:**

Этот вопрос касается понимания работы блока `finally` в конструкции `try...finally` в Python. Вот как это работает:

1.  **Блок `try`:** Сначала выполняется код внутри блока `try`. В данном случае это `return 1`. Обычно, при выполнении `return`, функция завершает свою работу и возвращает значение.
2.  **Блок `finally`:** Однако, перед тем как функция окончательно завершится, выполняется блок `finally`. Это происходит **всегда**, независимо от того, было ли исключение в блоке `try` или нет, и даже если в блоке `try` был выполнен оператор `return`.
3.  **Переопределение возвращаемого значения:** Внутри блока `finally` также находится `return 2`. Это `return` переопределяет значение, которое должно было быть возвращено из блока `try`. Таким образом, функция **всегда** возвращает значение из блока `finally`.

**Разбор вариантов:**
*   **A. 1:** Неправильно, так как значение из блока `try` переопределяется.
*   **B. 2:** Правильно, так как именно значение из блока `finally` возвращается функцией.
*   **C. None:** Неправильно, так как функция всегда возвращает значение (число).
*   **D. Произойдет ошибка:** Неправильно, код выполнится без ошибок.

**Вывод:**

В результате выполнения кода `foo()` функция вернет значение `2`, которое было возвращено из блока `finally`, даже если в блоке `try` был `return 1`. Таким образом, значение, возвращенное из блока `try`, игнорируется.

**Дополнительные важные моменты:**
*   Блок `finally` является критически важным для освобождения ресурсов (файлы, соединения с БД и т.д.), которые были захвачены в блоке `try`, независимо от того, возникли ли исключения или нет.
*   Возврат из блока `finally` может замаскировать ошибки, возникшие в блоке `try`. Поэтому важно использовать его аккуратно и с полным пониманием последствий.

**Пример более сложного случая с исключением:**
```python
def foo2():
    try:
        1 / 0
        return 1
    except ZeroDivisionError:
        return 3
    finally:
        return 2
result2 = foo2()
print(result2)
#Вывод: 2
```

Даже если в блоке `try` возникнет исключение `ZeroDivisionError` и он обработается в `except`, то все равно функция вернет значение `2`, которое возвращается из `finally`.

**В итоге:** Правильный ответ **B. 
2**. Блок `finally` всегда выполняется и переопределяет возвращаемое значение.
