### question_515.md

**Вопрос 515.** Как действует предложение `finally` в блоке `try-except`?

- A.  Оно выполняет код внутри него только в том случае, если в блоке `try` не было вызвано никаких исключений.
- B.  Оно выполняется независимо от того, было ли вызвано исключение или нет, и даже если был встречен оператор `return`.
- C.  Оно используется для вызова исключения, если оно не было вызвано в блоке `try`.
- D.  Оно предотвращает распространение любого исключения, вызванного в блоке `try`, далее.

**Правильный ответ: B**

**Объяснение:**

Предложение `finally` в блоке `try-except` предназначено для выполнения кода, который *должен* выполниться *всегда*, независимо от того, возникло ли исключение в блоке `try` или нет, или даже если был выполнен оператор `return`.

*   **Вариант A** не верен: Для этого используется `else`, а не `finally`.
*   **Вариант B** верен: Код в блоке `finally` выполняется независимо от того, как был выполнен блок `try`.
*   **Вариант C** не верен: Для вызова исключения используется `raise`, а не `finally`.
*   **Вариант D** не верен: `finally` не предотвращает распространение исключений, а лишь гарантирует выполнение кода.

**Как работает `try...except...finally`:**

1.  Выполняется код в блоке `try`.
2.  Если в блоке `try` возникает исключение, Python ищет соответствующий блок `except` для его обработки.
3.  **Независимо** от того, было ли исключение и был ли найден `except` блок, *всегда* выполняется код в блоке `finally`.
4.  Если исключения не было, то блок `finally` выполнится после блока `try`.
5.  Блок `finally` выполняется даже если блок `try` имеет оператор `return`, или даже если `except` содержит оператор `return`.

**Типичные применения `finally`:**

*   **Освобождение ресурсов:** Освобождение внешних ресурсов, таких как файлы, сокеты, или соединения с базами данных.
*   **Обеспечение корректного завершения:**  Выполнение финальных действий, которые должны быть гарантированно выполнены, независимо от успешного или неуспешного выполнения кода.

**Пример:**

```python
def my_function(num: int) -> int | None:
  """Проверяем число на четность и обрабатываем исключения с помощью try-except-finally"""
  try:
    result: int = 10 // num
    print(f"Результат деления: {result}")
    if num > 5:
       return result
  except ZeroDivisionError:
    print("Нельзя делить на ноль")
    return None # Возвращаем None если ошибка
  finally:
      print("Блок finally всегда выполняется")


res1 = my_function(2)
print(f"Результат: {res1}")

res2 = my_function(0) # Вызовется ZeroDivisionError
print(f"Результат: {res2}")

res3 = my_function(6)
print(f"Результат: {res3}")

# Вывод:
# Результат деления: 5
# Блок finally всегда выполняется
# Результат: 5
# Нельзя делить на ноль
# Блок finally всегда выполняется
# Результат: None
# Результат деления: 1
# Блок finally всегда выполняется
# Результат: 1
```

**В результате:**
* При вызове `my_function(2)` , код выполняется без ошибок и выполняется блок `finally` а затем результат возвращается.
* При вызове `my_function(0)` происходит `ZeroDivisionError`, код переходит в блок except, где обрабатывается исключение и возвращает `None` а также выполняет код из `finally` блока.
*  При вызове  `my_function(6)`  возвращается `result`, а также выполняется блок `finally`.

Таким образом, **вариант B** является правильным ответом.
**Исходный вопрос:**

Какой будет результат выполнения следующего кода?

```python
my_list = [1, 2, 3]
my_list.append(my_list)
print(my_list)
```

A. [1, 2, 3, [1, 2, 3]]
B. [1, 2, 3, [...]]
C. Ошибка переполнения стека
D. Выведет ошибку типа

**Правильный ответ: B**

**Объяснение:**

Этот вопрос проверяет понимание того, как работает метод `append` и как Python обрабатывает циклические ссылки в списках.

1. **Изначальный список:** `my_list` создается как `[1, 2, 3]`.
2. **Добавление списка к себе:** Метод `append(my_list)` добавляет *сам список* `my_list` в *конец* списка `my_list`. Это создает вложенный список и циклическую ссылку, потому что последний элемент `my_list` ссылается на сам `my_list`.
3. **Вывод:** Когда мы печатаем `my_list`, Python замечает циклическую ссылку и вместо того, чтобы пытаться бесконечно разворачивать вложенность, он обозначает эту ссылку как `[...]`.

**Разбор вариантов:**
*   **A. [1, 2, 3, [1, 2, 3]]**: Неправильно, Python не будет бесконечно раскрывать вложенность.
*   **B. [1, 2, 3, [...]]**: Правильно, Python обнаруживает циклическую ссылку и заменяет ее на `[...]`.
*   **C. Ошибка переполнения стека**: Неправильно, Python обрабатывает циклические ссылки таким образом, чтобы избежать переполнения стека.
*   **D. Выведет ошибку типа**: Неправильно, код выполняется без ошибок типов.

**Код для файла `question_515.md`:**

```markdown
### `question_515.md`

**Вопрос 515.** Какой будет результат выполнения следующего кода?

```python
my_list = [1, 2, 3]
my_list.append(my_list)
print(my_list)
```

- A.  [1, 2, 3, [1, 2, 3]]
- B.  [1, 2, 3, [...]]
- C.  Ошибка переполнения стека
- D.  Выведет ошибку типа

**Правильный ответ: B**

**Объяснение:**

Этот код демонстрирует, что происходит, когда список добавляет сам себя в качестве элемента.

1.  **Создание списка:** Изначально создается список `my_list` с элементами `[1, 2, 3]`.

2.  **Циклическая ссылка:** Метод `append(my_list)` добавляет сам список `my_list` в конец `my_list`. Это создает *циклическую ссылку*, где последний элемент списка ссылается на сам список.

3.  **Вывод:** При печати списка Python обнаруживает эту циклическую ссылку. Чтобы избежать бесконечного разворачивания вложенных структур, Python представляет циклически вложенный список как `[...]`.

**Дополнительные замечания:**
*   Такое поведение позволяет Python обрабатывать рекурсивные структуры данных, не вызывая ошибок переполнения стека.
*  Циклические ссылки могут возникать не только через append, но и при присваивании списков друг другу.
*   При работе с такими структурами важно понимать, что изменение одного списка может повлиять на другой, если они имеют общие ссылки.
```
